<?xml version='1.0'?>

<robot name="udacity_bot" xmlns:xacro="http://www.ros.org/wiki/xacro">
  
  <xacro:include filename="$(find udacity_bot)/urdf/modified/mod_udacity_bot.gazebo" />
  
  <link name="robot_footprint"></link>

  <joint name="robot_footprint_joint" type="fixed">
    <origin xyz="0.051 0 0" rpy="0 0 0" />
    <parent link="robot_footprint"/>
    <child link="chassis" />
  </joint>

  <link name='chassis'>
    <pose>0 0 0.1 0 0 0</pose>

    <inertial>
      <mass value="15.0"/>
      <origin xyz="0.0 0 0" rpy=" 0 0 0"/>
      <inertia
          ixx="0.1" ixy="0" ixz="0"
          iyy="0.1" iyz="0"
          izz="0.1"
      />
    </inertial>

    <collision name='collision'>
      <origin xyz="0 0 0" rpy=" 0 0 0"/> 
      <geometry>
        <box size=".158 .074 .01"/>
      </geometry>
    </collision>

    <visual name='chassis_visual'>
      <origin xyz="0 0 0" rpy=" 0 0 0"/>
      <geometry>
        <box size=".158 .074 .01"/>
      </geometry>
    </visual>
  </link>
  
  <link name="caster">
    <inertial>
      <mass value="5.0"/>
      <origin xyz="0.0 0 0" rpy=" 0 0 0"/>
      <inertia
          ixx="0.1" ixy="0" ixz="0"
          iyy="0.1" iyz="0"
          izz="0.1"
      />
    </inertial>
    
    <collision name='caster_collision'>
      <origin xyz="0 0 0" rpy=" 0 0 0"/>
      <geometry>
        <sphere radius="0.01"/>
      </geometry>
    </collision>

    <visual name='caster_visual'>
      <origin xyz="0 0 0" rpy=" 0 0 0"/>
      <geometry>
        <sphere radius="0.01"/>
      </geometry>
    </visual>
  </link>
  
  <link name='left_wheel'>
    <visual name='left_wheel_visual'>
      <origin xyz="0 0 0" rpy=" 0 1.5707 1.5707"/>
      <geometry>
        <cylinder radius='0.03' length='0.007'/>
      </geometry>
    </visual>
    
    <collision name='left_wheel_collision'>
      <origin xyz="0 0 0" rpy=" 0 1.5707 1.5707"/> 
      <geometry>
        <cylinder radius='0.03' length='0.007'/>
      </geometry>
    </collision>
    
    <inertial>
      <mass value="5.0"/>
      <origin xyz="0.0 0 0" rpy=" 0 0 0"/>
      <inertia
          ixx="0.1" ixy="0" ixz="0"
          iyy="0.1" iyz="0"
          izz="0.1"
      />
    </inertial>
  </link>

  <joint type="continuous" name="left_wheel_hinge">
    <origin xyz="0 0.0475 0" rpy="0 0 0"/>
    <child link="left_wheel"/>
    <parent link="robot_footprint"/>
    <axis xyz="0 1 0" rpy="0 0 0"/>
    <limit effort="10000" velocity="1000"/>
    <joint_properties damping="1.0" friction="1.0"/>
  </joint>
  
   <link name='right_wheel'>
    <visual name='right_wheel_visual'>
      <origin xyz="0 0 0" rpy=" 0 1.5707 1.5707"/>
      <geometry>
        <cylinder radius='0.03' length='0.007'/>
      </geometry>
    </visual>
    
    <collision name='right_wheel_collision'>
      <origin xyz="0 0 0" rpy=" 0 1.5707 1.5707"/> 
      <geometry>
        <cylinder radius='0.03' length='0.007'/>
      </geometry>
    </collision>
    
    <inertial>
      <mass value="5.0"/>
      <origin xyz="0.0 0 0" rpy=" 0 0 0"/>
      <inertia
          ixx="0.1" ixy="0" ixz="0"
          iyy="0.1" iyz="0"
          izz="0.1"
      />
    </inertial>
  </link>

  <joint type="continuous" name="right_wheel_hinge">
    <origin xyz="0 -0.0475 0" rpy="0 0 0"/>
    <child link="right_wheel"/>
    <parent link="robot_footprint"/>
    <axis xyz="0 1 0" rpy="0 0 0"/>
    <limit effort="10000" velocity="1000"/>
    <joint_properties damping="1.0" friction="1.0"/>
  </joint>

  <link name='camera'>
    <visual name='camera_visual'>
      <geometry>
        <box size='0.003 0.035 0.03'/>
      </geometry>
    </visual>
    
    <collision name='camera_collision'>
      <geometry>
        <box size='0.003 0.035 0.03'/>
      </geometry>
    </collision>
    
    <inertial>
      <mass value='1.0'/>
      <inertia
          ixx="1e-6" ixy="0" ixz="0"
          iyy="1e-6" iyz="0"
          izz="1e-6"
      />
    </inertial>
  </link>

  <joint type='fixed' name='caster_joint'>
    <origin xyz="0.025 0 -0.02" rpy="0 0 0"/>
    <child link='caster'/>
    <parent link='chassis'/>
  </joint>

  <joint type='fixed' name='camera_joint'>
    <origin xyz='0.063 0 0.02' rpy='0 0 0'/>
    <child link='camera'/>
    <parent link='chassis'/>
  </joint>
    
  <link name='hokuyo'>
    <visual name='hokuyo_visual'>
      <geometry>
        <mesh filename="package://udacity_bot/meshes/hokuyo.dae"/>
      </geometry>
    </visual>
    
    <collision name='hokuyo_collision'>
      <geometry>
        <mesh filename="package://udacity_bot/meshes/hokuyo.dae"/>
      </geometry>
    </collision>
    
    <inertial>
      <mass value='3.0'/>
      <inertia
          ixx="1e-6" ixy="0" ixz="0"
          iyy="1e-6" iyz="0"
          izz="1e-6"
      />
    </inertial>
  </link>
  
  <joint type='fixed' name='hokuyo_joint'>
    <origin xyz='0 0 0.04' rpy='0 0 0'/>
    <child link='hokuyo'/>
    <parent link='chassis'/>
  </joint>
  
  
</robot>



















